<?xml version="1.0" ?>
<!-- =================================================================================== -->
<!-- |    This document was autogenerated by xacro from hc10_with_env.xacro            | -->
<!-- |    EDITING THIS FILE BY HAND IS NOT RECOMMENDED                                 | -->
<!-- =================================================================================== -->
<robot name="yaskawa_1">
  <material name="silver">
    <color rgba="0.700 0.700 0.700 1.000"/>
  </material>
  <material name="dark_gray">
    <color rgba="0.3 0.3 0.3 1.000"/>
  </material>
  <material name="white_smoke">
    <color rgba="0.7607 0.7607 0.7607 1.000"/>
  </material>
  <!-- link list -->
  <link name="yaska1_base_link">
    <visual>
      <geometry>
        <mesh filename="package://motoman_hc10_support/meshes/hc10dt_b10/visual/base_link.dae"/>
      </geometry>
      <material name="">
        <color rgba="0.12941176470588237 0.14901960784313725 0.7490196078431373 1.0"/>
      </material>
    </visual>
    <collision>
      <geometry>
        <mesh filename="package://motoman_hc10_support/meshes/hc10dt_b10/collision/base_link.stl"/>
      </geometry>
    </collision>
  </link>
  <link name="yaska1_link_1_s">
    <visual>
      <geometry>
        <mesh filename="package://motoman_hc10_support/meshes/hc10dt_b10/visual/link_1_s.dae"/>
      </geometry>
      <material name="">
        <color rgba="0.12941176470588237 0.14901960784313725 0.7490196078431373 1.0"/>
      </material>
    </visual>
    <collision>
      <geometry>
        <mesh filename="package://motoman_hc10_support/meshes/hc10dt_b10/collision/link_1_s.stl"/>
      </geometry>
    </collision>
  </link>
  <link name="yaska1_link_2_l">
    <visual>
      <geometry>
        <mesh filename="package://motoman_hc10_support/meshes/hc10dt_b10/visual/link_2_l.dae"/>
      </geometry>
      <material name="">
        <color rgba="0.12941176470588237 0.14901960784313725 0.7490196078431373 1.0"/>
      </material>
    </visual>
    <collision>
      <geometry>
        <mesh filename="package://motoman_hc10_support/meshes/hc10dt_b10/collision/link_2_l.stl"/>
      </geometry>
    </collision>
  </link>
  <link name="yaska1_link_3_u">
    <visual>
      <geometry>
        <mesh filename="package://motoman_hc10_support/meshes/hc10dt_b10/visual/link_3_u.dae"/>
      </geometry>
      <material name="">
        <color rgba="0.12941176470588237 0.14901960784313725 0.7490196078431373 1.0"/>
      </material>
    </visual>
    <collision>
      <geometry>
        <mesh filename="package://motoman_hc10_support/meshes/hc10dt_b10/collision/link_3_u.stl"/>
      </geometry>
    </collision>
  </link>
  <link name="yaska1_link_4_r">
    <visual>
      <geometry>
        <mesh filename="package://motoman_hc10_support/meshes/hc10dt_b10/visual/link_4_r.dae"/>
      </geometry>
      <material name="">
        <color rgba="0.12941176470588237 0.14901960784313725 0.7490196078431373 1.0"/>
      </material>
    </visual>
    <collision>
      <geometry>
        <mesh filename="package://motoman_hc10_support/meshes/hc10dt_b10/collision/link_4_r.stl"/>
      </geometry>
    </collision>
  </link>
  <link name="yaska1_link_5_b">
    <visual>
      <geometry>
        <mesh filename="package://motoman_hc10_support/meshes/hc10dt_b10/visual/link_5_b.dae"/>
      </geometry>
      <material name="">
        <color rgba="0.12941176470588237 0.14901960784313725 0.7490196078431373 1.0"/>
      </material>
    </visual>
    <collision>
      <geometry>
        <mesh filename="package://motoman_hc10_support/meshes/hc10dt_b10/collision/link_5_b.stl"/>
      </geometry>
    </collision>
  </link>
  <link name="yaska1_link_6_t">
    <visual>
      <geometry>
        <mesh filename="package://motoman_hc10_support/meshes/hc10dt_b10/visual/link_6_t.dae"/>
      </geometry>
      <material name="">
        <color rgba="0.12941176470588237 0.14901960784313725 0.7490196078431373 1.0"/>
      </material>
    </visual>
    <collision>
      <geometry>
        <mesh filename="package://motoman_hc10_support/meshes/hc10dt_b10/collision/link_6_t.stl"/>
      </geometry>
    </collision>
  </link>
  <!-- end of link list -->
  <!-- joint list -->
  <joint name="yaska1_joint_1_s" type="revolute">
    <parent link="yaska1_base_link"/>
    <child link="yaska1_link_1_s"/>
    <origin rpy="0 0 1.5707963267948966" xyz="0 0 0.275"/>
    <axis xyz="0 0 1"/>
    <limit effort="368.48" lower="-3.141592653589793" upper="3.141592653589793" velocity="2.2689280275926285"/>
  </joint>
  <joint name="yaska1_joint_2_l" type="revolute">
    <parent link="yaska1_link_1_s"/>
    <child link="yaska1_link_2_l"/>
    <origin rpy="0 0 0" xyz="0 0 0"/>
    <axis xyz="0 1 0"/>
    <limit effort="414.54" lower="-3.141592653589793" upper="3.141592653589793" velocity="2.2689280275926285"/>
  </joint>
  <joint name="yaska1_joint_3_u" type="revolute">
    <parent link="yaska1_link_2_l"/>
    <child link="yaska1_link_3_u"/>
    <origin rpy="0 0 0" xyz="0 0 0.700"/>
    <axis xyz="0 -1 0"/>
    <limit effort="158.76" lower="-1.6580627893946132" upper="4.625122517784973" velocity="3.141592653589793"/>
  </joint>
  <joint name="yaska1_joint_4_r" type="revolute">
    <parent link="yaska1_link_3_u"/>
    <child link="yaska1_link_4_r"/>
    <origin rpy="0 0 0" xyz="0.500 0 0"/>
    <axis xyz="-1 0 0"/>
    <limit effort="41.16" lower="-3.141592653589793" upper="3.141592653589793" velocity="3.141592653589793"/>
  </joint>
  <joint name="yaska1_joint_5_b" type="revolute">
    <parent link="yaska1_link_4_r"/>
    <child link="yaska1_link_5_b"/>
    <origin rpy="0 0 0" xyz="0 0.162 0"/>
    <axis xyz="0 -1 0"/>
    <limit effort="33.32" lower="-3.141592653589793" upper="3.141592653589793" velocity="4.363323129985824"/>
  </joint>
  <joint name="yaska1_joint_6_t" type="revolute">
    <parent link="yaska1_link_5_b"/>
    <child link="yaska1_link_6_t"/>
    <origin rpy="0 0 0" xyz="0 0 0"/>
    <axis xyz="-1 0 0"/>
    <limit effort="31.36" lower="-3.141592653589793" upper="3.141592653589793" velocity="4.363323129985824"/>
  </joint>
  <!-- end of joint list -->
  <!-- ROS-Industrial 'flange' frame: attachment point for EEF models -->
  <link name="yaska1_flange"/>
  <joint name="yaska1_joint_6_t-flange" type="fixed">
    <origin rpy="0 0 0" xyz="0.170 0 0"/>
    <parent link="yaska1_link_6_t"/>
    <child link="yaska1_flange"/>
  </joint>
  <!-- ROS-Industrial 'tool0' frame: all-zeros tool frame -->
  <link name="yaska1_tool0"/>
  <joint name="yaska1_flange-tool0" type="fixed">
    <origin rpy="3.141592653589793 -1.5707963267948966 0" xyz="0 0 0"/>
    <parent link="yaska1_flange"/>
    <child link="yaska1_tool0"/>
  </joint>
  <!-- ROS base_link to Robot Manufacturer World Coordinates transform -->
  <link name="yaska1_base"/>
  <joint name="yaska1_base_link-base" type="fixed">
    <origin rpy="0 0 0" xyz="0 0 0.275"/>
    <parent link="yaska1_base_link"/>
    <child link="yaska1_base"/>
  </joint>
  <link name="table_link">
    <visual>
      <origin rpy="0 0 0" xyz="0 0 0"/>
      <geometry>
        <mesh filename="package://motoman_hc10_support/meshes/env/table_yaskawa.stl" scale="1 1 1"/>
      </geometry>
      <material name="silver"/>
    </visual>
    <collision>
      <origin rpy="0 0 0" xyz="0 0 0"/>
      <geometry>
        <mesh filename="package://motoman_hc10_support/meshes/env/table_yaskawa.stl" scale="1 1 1"/>
      </geometry>
    </collision>
  </link>
  <link name="pieds_cellule_link">
    <visual>
      <origin rpy="0 0 0" xyz="0 0 0"/>
      <geometry>
        <mesh filename="package://motoman_hc10_support/meshes/env/pieds_cellule.stl" scale="1 1 1"/>
      </geometry>
      <material name="silver"/>
    </visual>
    <collision>
      <origin rpy="0 0 0" xyz="0 0 0"/>
      <geometry>
        <mesh filename="package://motoman_hc10_support/meshes/env/pieds_cellule.stl" scale="1 1 1"/>
      </geometry>
    </collision>
  </link>
  <link name="ergots1_link">
    <visual>
      <origin rpy="0 0 0" xyz="0 0 0"/>
      <geometry>
        <mesh filename="package://motoman_hc10_support/meshes/env/ergots.stl" scale="0.001 0.001 0.001"/>
      </geometry>
      <material name="dark_gray"/>
    </visual>
    <collision>
      <origin rpy="0 0 0" xyz="0 0 0"/>
      <geometry>
        <mesh filename="package://motoman_hc10_support/meshes/env/ergots.stl" scale="0.001 0.001 0.001"/>
      </geometry>
    </collision>
  </link>
  <link name="ergots2_link">
    <visual>
      <origin rpy="0 0 0" xyz="0 0 0"/>
      <geometry>
        <mesh filename="package://motoman_hc10_support/meshes/env/ergots.stl" scale="0.001 0.001 0.001"/>
      </geometry>
      <material name="dark_gray"/>
    </visual>
    <collision>
      <origin rpy="0 0 0" xyz="0 0 0"/>
      <geometry>
        <mesh filename="package://motoman_hc10_support/meshes/env/ergots.stl" scale="0.001 0.001 0.001"/>
      </geometry>
    </collision>
  </link>
  <link name="rail_milieu_link">
    <visual>
      <origin rpy="0 0 0" xyz="0 0 0"/>
      <geometry>
        <mesh filename="package://motoman_hc10_support/meshes/env/rail_milieu.stl" scale="0.001 0.001 0.001"/>
      </geometry>
      <material name="silver"/>
    </visual>
    <collision>
      <origin rpy="0 0 0" xyz="0 0 0"/>
      <geometry>
        <mesh filename="package://motoman_hc10_support/meshes/env/rail_milieu.stl" scale="0.001 0.001 0.001"/>
      </geometry>
    </collision>
  </link>
  <link name="rail_tournant1_link">
    <visual>
      <origin rpy="0 0 0" xyz="0 0 0"/>
      <geometry>
        <mesh filename="package://motoman_hc10_support/meshes/env/rail_tournant.stl" scale="0.001 0.001 0.001"/>
      </geometry>
      <material name="silver"/>
    </visual>
    <collision>
      <origin rpy="0 0 0" xyz="0 0 0"/>
      <geometry>
        <mesh filename="package://motoman_hc10_support/meshes/env/rail_tournant.stl" scale="0.001 0.001 0.001"/>
      </geometry>
    </collision>
  </link>
  <link name="rail_tournant2_link">
    <visual>
      <origin rpy="0 0 0" xyz="0 0 0"/>
      <geometry>
        <mesh filename="package://motoman_hc10_support/meshes/env/rail_tournant.stl" scale="0.001 0.001 0.001"/>
      </geometry>
      <material name="silver"/>
    </visual>
    <collision>
      <origin rpy="0 0 0" xyz="0 0 0"/>
      <geometry>
        <mesh filename="package://motoman_hc10_support/meshes/env/rail_tournant.stl" scale="0.001 0.001 0.001"/>
      </geometry>
    </collision>
  </link>
  <joint name="pieds_cellule_ergots1" type="fixed">
    <origin rpy="0 0 0" xyz="0.111 0.025 0.485"/>
    <parent link="pieds_cellule_link"/>
    <child link="ergots1_link"/>
  </joint>
  <joint name="pieds_cellule_ergots2" type="fixed">
    <origin rpy="0 0 0" xyz="-0.29 0.025 0.485"/>
    <parent link="pieds_cellule_link"/>
    <child link="ergots2_link"/>
  </joint>
  <joint name="pieds_cellule_rail_milieu" type="fixed">
    <origin rpy="0 0 0" xyz="-0.02 0 0.403"/>
    <parent link="pieds_cellule_link"/>
    <child link="rail_milieu_link"/>
  </joint>
  <joint name="rail_milieu_rail_tournant1" type="fixed">
    <origin rpy="-1.57079 3.14 1.57079" xyz="0.69 0.09 0.003"/>
    <parent link="rail_milieu_link"/>
    <child link="rail_tournant1_link"/>
  </joint>
  <joint name="rail_milieu_rail_tournant2" type="fixed">
    <origin rpy="-1.57079 3.14 0" xyz="-0.651 0.09 0.003"/>
    <parent link="rail_milieu_link"/>
    <child link="rail_tournant2_link"/>
  </joint>
  <!-- Ajout des différentes pièces de la pinces / couleurs définies dans le fichier materials.xacro-->
  <link name="adaptater_plate_link">
    <visual>
      <geometry>
        <mesh filename="package://motoman_hc10_support/meshes/hand/LWR50F-17-04-A.stl" scale="0.001 0.001 0.001"/>
      </geometry>
      <material name="dark_gray"/>
    </visual>
    <collision>
      <geometry>
        <mesh filename="package://motoman_hc10_support/meshes/hand/LWR50F-17-04-A.stl" scale="0.001 0.001 0.001"/>
      </geometry>
    </collision>
  </link>
  <link name="end_effector_link">
    <visual>
      <geometry>
        <mesh filename="package://motoman_hc10_support/meshes/hand/end_effector_LWR50L-03-00001-A.stl" scale="0.001 0.001 0.001"/>
      </geometry>
      <material name="white_smoke"/>
    </visual>
    <collision>
      <geometry>
        <mesh filename="package://motoman_hc10_support/meshes/hand/end_effector_LWR50L-03-00001-A.stl" scale="0.001 0.001 0.001"/>
      </geometry>
    </collision>
  </link>
  <link name="mors_link1">
    <visual>
      <geometry>
        <mesh filename="package://motoman_hc10_support/meshes/hand/mors_for_LWR50L-03-00001-A.stl" scale="0.001 0.001 0.001"/>
      </geometry>
      <material name="silver"/>
    </visual>
    <collision>
      <geometry>
        <mesh filename="package://motoman_hc10_support/meshes/hand/mors_for_LWR50L-03-00001-A.stl" scale="0.001 0.001 0.001"/>
      </geometry>
    </collision>
  </link>
  <link name="mors_link2">
    <visual>
      <geometry>
        <mesh filename="package://motoman_hc10_support/meshes/hand/mors_for_LWR50L-03-00001-A.stl" scale="0.001 0.001 0.001"/>
      </geometry>
      <material name="silver"/>
    </visual>
    <collision>
      <geometry>
        <mesh filename="package://motoman_hc10_support/meshes/hand/mors_for_LWR50L-03-00001-A.stl" scale="0.001 0.001 0.001"/>
      </geometry>
    </collision>
  </link>
  <!-- Création des joints  -->
  <joint name="adapatater_plate_end_effector" type="fixed">
    <origin rpy="0 1.57079 0" xyz="0 -0.039 0"/>
    <parent link="adaptater_plate_link"/>
    <child link="end_effector_link"/>
  </joint>
  <!-- ce joint doit être de type prismatique -->
  <joint name="end_effector_mors1" type="prismatic">
    <origin rpy="0 0 0" xyz="0 0 0"/>
    <parent link="end_effector_link"/>
    <child link="mors_link1"/>
    <axis xyz="0 0 1"/>
    <limit effort="1000.0" lower="-0.0108" upper="0" velocity="0.5"/>
  </joint>
  <!-- ce joint doit être de type prismatique -->
  <joint name="end_effector_adaptater_mors2" type="prismatic">
    <origin rpy="0 3.14 0" xyz="0 0 0"/>
    <parent link="end_effector_link"/>
    <child link="mors_link2"/>
    <axis xyz="0 0 1"/>
    <limit effort="1000.0" lower="-0.0108" upper="0" velocity="0.5"/>
  </joint>
  <!-- linking robot to world,workspaces and end-effector -->
  <link name="world"/>
  <joint name="world_cell" type="fixed">
    <origin rpy="0 0 -1.57079" xyz="0.72 0.27 0.698"/>
    <parent link="world"/>
    <child link="pieds_cellule_link"/>
  </joint>
  <joint name="world_table" type="fixed">
    <origin rpy="1.57079 0 0" xyz="0 0 0.432"/>
    <parent link="world"/>
    <child link="table_link"/>
  </joint>
  <joint name="table_yaska1" type="fixed">
    <origin rpy="-1.57079 1.57079 0" xyz="0.171 0.203 0.181"/>
    <parent link="table_link"/>
    <child link="yaska1_base_link"/>
  </joint>
  <joint name="tool_adaptater" type="fixed">
    <origin rpy="-1.57079 0 -1.57079" xyz="0 0 0"/>
    <parent link="yaska1_tool0"/>
    <child link="adaptater_plate_link"/>
  </joint>
</robot>

